<sdf version='1.6'>
  <world name='default'>
    <light name='sun' type='directional'>
      <cast_shadows>1</cast_shadows>
      <pose frame=''>0 0 10 0 -0 0</pose>
      <diffuse>0.8 0.8 0.8 1</diffuse>
      <specular>0.2 0.2 0.2 1</specular>
      <attenuation>
        <range>1000</range>
        <constant>0.9</constant>
        <linear>0.01</linear>
        <quadratic>0.001</quadratic>
      </attenuation>
      <direction>-0.5 0.1 -0.9</direction>
    </light>
    <model name='ground_plane'>
      <static>1</static>
      <link name='link'>
        <collision name='collision'>
          <geometry>
            <plane>
              <normal>0 0 1</normal>
              <size>100 100</size>
            </plane>
          </geometry>
          <surface>
            <friction>
              <ode>
                <mu>100</mu>
                <mu2>50</mu2>
              </ode>
            </friction>
            <contact>
              <ode/>
            </contact>
            <bounce/>
          </surface>
          <max_contacts>10</max_contacts>
        </collision>
        <visual name='visual'>
          <cast_shadows>0</cast_shadows>
          <geometry>
            <plane>
              <normal>0 0 1</normal>
              <size>100 100</size>
            </plane>
          </geometry>
          <material>
            <script>
              <uri>file://media/materials/scripts/gazebo.material</uri>
              <name>Gazebo/Grey</name>
            </script>
          </material>
        </visual>
        <self_collide>0</self_collide>
        <kinematic>0</kinematic>
        <gravity>1</gravity>
        <enable_wind>0</enable_wind>
      </link>
    </model>
    <physics name='dart_2ms' default='0' type='dart'>
      <max_step_size>0.002</max_step_size>
      <real_time_factor>1</real_time_factor>
      <real_time_update_rate>500</real_time_update_rate>
      <dart>
        <solver>
          <solver_type>pgs</solver_type>
        </solver>
      </dart>
    </physics>
    <scene>
      <ambient>0.4 0.4 0.4 1</ambient>
      <background>0.7 0.7 0.7 1</background>
      <shadows>1</shadows>
    </scene>
    <spherical_coordinates>
      <surface_model>EARTH_WGS84</surface_model>
      <latitude_deg>0</latitude_deg>
      <longitude_deg>0</longitude_deg>
      <elevation>0</elevation>
      <heading_deg>0</heading_deg>
    </spherical_coordinates>
    <state world_name='default'>
      <sim_time>536 228000000</sim_time>
      <real_time>0 0</real_time>
      <wall_time>1627304112 311456869</wall_time>
      <iterations>5211</iterations>
      <model name='cabinet_door_fragile'>
        <pose frame=''>-0.304571 0.994618 0.775 0 0 -1.5539</pose>
        <scale>1 1 1</scale>
        <link name='cabinet'>
          <pose frame=''>-0.304571 0.994618 1.125 0 0 -1.5539</pose>
          <velocity>-0 -0 -0 0 -0 0</velocity>
          <acceleration>0 0 0 0 -0 0</acceleration>
          <wrench>0 0 0 0 -0 0</wrench>
        </link>
        <link name='left_door'>
          <pose frame=''>-0.58575 0.854847 1.1625 0 0 -1.5539</pose>
          <velocity>-0 -0 -0 0 -0 0</velocity>
          <acceleration>0 0 0 0 -0 0</acceleration>
          <wrench>0 0 0 0 -0 0</wrench>
        </link>
        <link name='left_handle'>
          <pose frame=''>-0.329559 0.81613 1.0945 0 0 -1.5539</pose>
          <velocity>-0 -0 -0 0 -0 0</velocity>
          <acceleration>0 0 0 -0 -0 -0</acceleration>
          <wrench>0 0 0 0 -0 0</wrench>
        </link>
        <link name='left_handle_dummy'>
          <pose frame=''>-0.329559 0.81613 1.0945 0 0 -1.5539</pose>
          <velocity>-0 -0 -0 0 -0 0</velocity>
          <acceleration>0 0 0 0 -0 0</acceleration>
          <wrench>0 0 0 0 -0 0</wrench>
        </link>
        <link name='right_door'>
          <pose frame=''>-0.018831 0.864427 1.1625 0 0 -1.5539</pose>
          <velocity>-0 -0 0 0 -0 0</velocity>
          <acceleration>0 0 0 0 -0 0</acceleration>
          <wrench>0 0 0 0 -0 0</wrench>
        </link>
        <link name='right_handle'>
          <pose frame=''>-0.273567 0.817076 1.0945 0 0 -1.5539</pose>
          <velocity>-0 -0 -0 0 -0 0</velocity>
          <acceleration>0 0 0 0 -0 0</acceleration>
          <wrench>0 0 0 0 -0 0</wrench>
        </link>
        <link name='right_handle_dummy'>
          <pose frame=''>-0.273567 0.817076 1.0945 0 0 -1.5539</pose>
          <velocity>-0 -0 -0 0 -0 0</velocity>
          <acceleration>0 0 0 -0 -0 -0</acceleration>
          <wrench>0 0 0 0 -0 0</wrench>
        </link>
      </model>
      <model name='cafe_table'>
        <pose frame=''>-0.311409 1.14853 0 0 -0 0</pose>
        <scale>1 1 1</scale>
        <link name='link'>
          <pose frame=''>-0.311409 1.14853 0 0 -0 0</pose>
          <velocity>0 0 0 0 -0 0</velocity>
          <acceleration>0 0 0 0 -0 0</acceleration>
          <wrench>0 0 0 0 -0 0</wrench>
        </link>
      </model>
      <model name='cafe_table_clone'>
        <pose frame=''>2.46582 0.001091 0 0 -0 0</pose>
        <scale>1 1 1</scale>
        <link name='link'>
          <pose frame=''>2.46582 0.001091 0 0 -0 0</pose>
          <velocity>0 0 0 0 -0 0</velocity>
          <acceleration>0 0 0 0 -0 0</acceleration>
          <wrench>0 0 0 0 -0 0</wrench>
        </link>
      </model>
      <model name='cafe_table_clone_clone'>
        <pose frame=''>1.10343 1.1323 0 0 -0 0</pose>
        <scale>1 1 1</scale>
        <link name='link'>
          <pose frame=''>1.10343 1.1323 0 0 -0 0</pose>
          <velocity>0 0 0 0 -0 0</velocity>
          <acceleration>0 0 0 0 -0 0</acceleration>
          <wrench>0 0 0 0 -0 0</wrench>
        </link>
      </model>
      <model name='demo_spam'>
        <pose frame=''>2.19932 -0.140934 0.81675 -4e-06 1.4e-05 -0.004158</pose>
        <scale>1 1 1</scale>
        <link name='link'>
          <pose frame=''>2.19932 -0.140934 0.81675 -4e-06 1.4e-05 -0.004158</pose>
          <velocity>-0 6e-06 3e-06 -0.000112 -7e-06 -3e-06</velocity>
          <acceleration>0 0 0 0 -0 0</acceleration>
          <wrench>0 0 0 0 -0 0</wrench>
        </link>
      </model>
      <model name='ground_plane'>
        <pose frame=''>0 0 0 0 -0 0</pose>
        <scale>1 1 1</scale>
        <link name='link'>
          <pose frame=''>0 0 0 0 -0 0</pose>
          <velocity>0 0 0 0 -0 0</velocity>
          <acceleration>0 0 0 0 -0 0</acceleration>
          <wrench>0 0 0 0 -0 0</wrench>
        </link>
      </model>
      <model name='jar'>
        <pose frame=''>1.07424 1.05324 0.875 2e-06 4e-06 -1.5533</pose>
        <scale>1 1 1</scale>
        <link name='link'>
          <pose frame=''>1.07424 1.05324 0.875 2e-06 4e-06 -1.5533</pose>
          <velocity>2e-06 3e-06 1e-06 -2.6e-05 1.8e-05 -1e-06</velocity>
          <acceleration>0 0 0 -0 -0 -0</acceleration>
          <wrench>0 0 0 0 -0 0</wrench>
        </link>
      </model>
      <model name='teapot'>
        <pose frame=''>0.801495 0.935165 0.774975 -0.000139 0.000473 1.56077</pose>
        <scale>1 1 1</scale>
        <link name='link'>
          <pose frame=''>0.801495 0.935165 0.774975 -0.000139 0.000473 1.56077</pose>
          <velocity>0 -0 0.000127 0 -0 0</velocity>
          <acceleration>0 0 0 0 -0 0</acceleration>
          <wrench>0 0 0 0 -0 0</wrench>
        </link>
      </model>
      <light name='sun'>
        <pose frame=''>0 0 10 0 -0 0</pose>
      </light>
    </state>
    <gui fullscreen='0'>
      <camera name='user_camera'>
        <pose frame=''>1.00929 -1.3076 3.64835 0 1.4098 1.48016</pose>
        <view_controller>orbit</view_controller>
        <projection_type>perspective</projection_type>
      </camera>
    </gui>
    <gravity>0 0 -9.8</gravity>
    <magnetic_field>6e-06 2.3e-05 -4.2e-05</magnetic_field>
    <atmosphere type='adiabatic'/>
    <audio>
      <device>default</device>
    </audio>
    <wind/>
    <model name='jar'>
      <link name='link'>
        <gravity>1</gravity>
        <inertial>
          <pose frame=''>0 0 0 0 -0 0</pose>
          <mass>0.2</mass>
          <inertia>
            <ixx>0.00079</ixx>
            <ixy>0</ixy>
            <ixz>0</ixz>
            <iyy>0.00079</iyy>
            <iyz>0</iyz>
            <izz>0.00025</izz>
          </inertia>
        </inertial>
        <collision name='collision'>
          <pose frame=''>0 0 0 0 -0 0</pose>
          <geometry>
            <mesh>
              <uri>model://jar_marker/meshes/jar_marker.dae</uri>
            </mesh>
          </geometry>
          <surface>
            <friction>
              <ode>
                <mu>1</mu>
                <mu2>1</mu2>
              </ode>
            </friction>
            <contact>
              <ode>
                <kp>1e+07</kp>
                <kd>1</kd>
                <min_depth>0.001</min_depth>
                <max_vel>0.1</max_vel>
              </ode>
            </contact>
          </surface>
          <max_contacts>10</max_contacts>
        </collision>
        <visual name='visual'>
          <pose frame=''>0 0 0 0 -0 0</pose>
          <geometry>
            <mesh>
              <uri>model://jar_marker/meshes/jar_marker.dae</uri>
            </mesh>
          </geometry>
        </visual>
        <self_collide>0</self_collide>
        <enable_wind>0</enable_wind>
      </link>
      <pose frame=''>0.849352 -0.297472 0 0 -0 0</pose>
    </model>
    <model name='cafe_table'>
      <static>1</static>
      <link name='link'>
        <collision name='surface'>
          <pose frame=''>0 0 0.755 0 -0 0</pose>
          <geometry>
            <box>
              <size>0.913 0.913 0.04</size>
            </box>
          </geometry>
          <max_contacts>10</max_contacts>
          <surface>
            <contact/>
            <friction>
              <ode/>
            </friction>
          </surface>
        </collision>
        <collision name='column'>
          <pose frame=''>0 0 0.37 0 -0 0</pose>
          <geometry>
            <box>
              <size>0.042 0.042 0.74</size>
            </box>
          </geometry>
          <max_contacts>10</max_contacts>
          <surface>
            <contact/>
            <friction>
              <ode/>
            </friction>
          </surface>
        </collision>
        <collision name='base'>
          <pose frame=''>0 0 0.02 0 -0 0</pose>
          <geometry>
            <box>
              <size>0.56 0.56 0.04</size>
            </box>
          </geometry>
          <max_contacts>10</max_contacts>
          <surface>
            <contact/>
            <friction>
              <ode/>
            </friction>
          </surface>
        </collision>
        <visual name='visual'>
          <geometry>
            <mesh>
              <uri>model://cafe_table/meshes/cafe_table.dae</uri>
            </mesh>
          </geometry>
        </visual>
        <self_collide>0</self_collide>
        <enable_wind>0</enable_wind>
        <gravity>1</gravity>
      </link>
      <pose frame=''>-1.17565 1.19758 0 0 -0 0</pose>
    </model>
    <model name='cabinet_door_fragile'>
      <plugin name='BreakableJoint' filename='libbreakable_joint.so'>
        <joint_name>right_handle_joint</joint_name>
        <pos_min>-0.05</pos_min>
        <pos_max>0.05</pos_max>
      </plugin>
      <plugin name='BreakableJoint' filename='libbreakable_joint.so'>
        <joint_name>right_handle_joint2</joint_name>
        <pos_min>-0.05</pos_min>
        <pos_max>0.05</pos_max>
      </plugin>
      <plugin name='BreakableJoint' filename='libbreakable_joint.so'>
        <joint_name>left_handle_joint</joint_name>
        <pos_min>-0.05</pos_min>
        <pos_max>0.05</pos_max>
      </plugin>
      <plugin name='BreakableJoint' filename='libbreakable_joint.so'>
        <joint_name>left_handle_joint2</joint_name>
        <pos_min>-0.05</pos_min>
        <pos_max>0.05</pos_max>
      </plugin>
      <link name='cabinet'>
        <pose frame=''>0 0 0.35 0 -0 0</pose>
        <inertial>
          <mass>16</mass>
          <pose frame=''>0 0 0 0 -0 0</pose>
          <inertia>
            <ixx>1.59</ixx>
            <ixy>0</ixy>
            <ixz>0</ixz>
            <iyy>1.12</iyy>
            <iyz>0</iyz>
            <izz>0.91</izz>
          </inertia>
        </inertial>
        <collision name='back'>
          <pose frame=''>-0.14 0 0.035 0 -0 0</pose>
          <geometry>
            <box>
              <size>0.015 0.585 0.6</size>
            </box>
          </geometry>
          <max_contacts>10</max_contacts>
          <surface>
            <contact/>
            <friction>
              <ode/>
            </friction>
          </surface>
        </collision>
        <visual name='visual1'>
          <pose frame=''>-0.14 0 0.035 0 -0 0</pose>
          <geometry>
            <box>
              <size>0.015 0.585 0.6</size>
            </box>
          </geometry>
          <material>
            <script>
              <uri>file://media/materials/scripts/gazebo.material</uri>
              <name>Gazebo/Wood</name>
            </script>
          </material>
        </visual>
        <collision name='left_side'>
          <pose frame=''>0 -0.2925 0 0 -0 0</pose>
          <geometry>
            <box>
              <size>0.3 0.015 0.7</size>
            </box>
          </geometry>
          <max_contacts>10</max_contacts>
          <surface>
            <contact/>
            <friction>
              <ode/>
            </friction>
          </surface>
        </collision>
        <visual name='visual2'>
          <pose frame=''>0 -0.2925 0 0 -0 0</pose>
          <geometry>
            <box>
              <size>0.3 0.015 0.7</size>
            </box>
          </geometry>
          <material>
            <script>
              <uri>file://media/materials/scripts/gazebo.material</uri>
              <name>Gazebo/Wood</name>
            </script>
          </material>
        </visual>
        <collision name='right_side'>
          <pose frame=''>0 0.2925 0 0 -0 0</pose>
          <geometry>
            <box>
              <size>0.3 0.015 0.7</size>
            </box>
          </geometry>
          <max_contacts>10</max_contacts>
          <surface>
            <contact/>
            <friction>
              <ode/>
            </friction>
          </surface>
        </collision>
        <visual name='visual3'>
          <pose frame=''>0 0.2925 0 0 -0 0</pose>
          <geometry>
            <box>
              <size>0.3 0.015 0.7</size>
            </box>
          </geometry>
          <material>
            <script>
              <uri>file://media/materials/scripts/gazebo.material</uri>
              <name>Gazebo/Wood</name>
            </script>
          </material>
        </visual>
        <collision name='bottom'>
          <pose frame=''>-0.002 0 -0.2525 0 -0 0</pose>
          <geometry>
            <box>
              <size>0.26 0.57 0.015</size>
            </box>
          </geometry>
          <max_contacts>10</max_contacts>
          <surface>
            <contact/>
            <friction>
              <ode/>
            </friction>
          </surface>
        </collision>
        <visual name='visual4'>
          <pose frame=''>-0.002 0 -0.2525 0 -0 0</pose>
          <geometry>
            <box>
              <size>0.26 0.57 0.015</size>
            </box>
          </geometry>
          <material>
            <script>
              <uri>file://media/materials/scripts/gazebo.material</uri>
              <name>Gazebo/Wood</name>
            </script>
          </material>
        </visual>
        <collision name='top'>
          <pose frame=''>0 0 0.3425 0 -0 0</pose>
          <geometry>
            <box>
              <size>0.3 0.57 0.015</size>
            </box>
          </geometry>
          <max_contacts>10</max_contacts>
          <surface>
            <contact/>
            <friction>
              <ode/>
            </friction>
          </surface>
        </collision>
        <visual name='visual5'>
          <pose frame=''>0 0 0.3425 0 -0 0</pose>
          <geometry>
            <box>
              <size>0.3 0.57 0.015</size>
            </box>
          </geometry>
          <material>
            <script>
              <uri>file://media/materials/scripts/gazebo.material</uri>
              <name>Gazebo/Wood</name>
            </script>
          </material>
        </visual>
        <collision name='middle_shelf'>
          <pose frame=''>-0.002 0 0.0475 0 -0 0</pose>
          <geometry>
            <box>
              <size>0.26 0.57 0.015</size>
            </box>
          </geometry>
          <max_contacts>10</max_contacts>
          <surface>
            <contact/>
            <friction>
              <ode/>
            </friction>
          </surface>
        </collision>
        <visual name='visual6'>
          <pose frame=''>-0.002 0 0.0475 0 -0 0</pose>
          <geometry>
            <box>
              <size>0.26 0.57 0.015</size>
            </box>
          </geometry>
          <material>
            <script>
              <uri>file://media/materials/scripts/gazebo.material</uri>
              <name>Gazebo/Wood</name>
            </script>
          </material>
        </visual>
        <collision name='low_front'>
          <pose frame=''>0.115 0 -0.3025 0 -0 0</pose>
          <geometry>
            <box>
              <size>0.015 0.57 0.09</size>
            </box>
          </geometry>
          <max_contacts>10</max_contacts>
          <surface>
            <contact/>
            <friction>
              <ode/>
            </friction>
          </surface>
        </collision>
        <visual name='visual7'>
          <pose frame=''>0.115 0 -0.3025 0 -0 0</pose>
          <geometry>
            <box>
              <size>0.015 0.57 0.09</size>
            </box>
          </geometry>
          <material>
            <script>
              <uri>file://media/materials/scripts/gazebo.material</uri>
              <name>Gazebo/Wood</name>
            </script>
          </material>
        </visual>
        <self_collide>0</self_collide>
        <enable_wind>0</enable_wind>
        <gravity>1</gravity>
      </link>
      <link name='right_door'>
        <pose frame=''>0.135 0.2835 0.3875 0 -0 0</pose>
        <inertial>
          <mass>1.7</mass>
          <pose frame=''>0 -0.141 0 0 -0 0</pose>
          <inertia>
            <ixx>0.06</ixx>
            <ixy>0</ixy>
            <ixz>0</ixz>
            <iyy>0.49</iyy>
            <iyz>0</iyz>
            <izz>0.111</izz>
          </inertia>
        </inertial>
        <collision name='right_face'>
          <pose frame=''>0 -0.141 0 0 -0 0</pose>
          <geometry>
            <box>
              <size>0.015 0.282 0.595</size>
            </box>
          </geometry>
          <max_contacts>10</max_contacts>
          <surface>
            <contact/>
            <friction>
              <ode/>
            </friction>
          </surface>
        </collision>
        <visual name='right_face_vis'>
          <pose frame=''>0 -0.141 0 0 -0 0</pose>
          <geometry>
            <box>
              <size>0.015 0.282 0.595</size>
            </box>
          </geometry>
          <material>
            <script>
              <uri>file://media/materials/scripts/gazebo.material</uri>
              <name>Gazebo/Wood</name>
            </script>
          </material>
        </visual>
        <collision name='right_handle_up'>
          <pose frame=''>0.02475 -0.2555 0.0656 0 -0 0</pose>
          <geometry>
            <box>
              <size>0.04 0.005 0.005</size>
            </box>
          </geometry>
          <max_contacts>10</max_contacts>
          <surface>
            <contact/>
            <friction>
              <ode/>
            </friction>
          </surface>
        </collision>
        <visual name='right_handle_up_vis'>
          <pose frame=''>0.02475 -0.2555 0.0656 0 -0 0</pose>
          <geometry>
            <box>
              <size>0.04 0.005 0.005</size>
            </box>
          </geometry>
          <material>
            <script>
              <uri>file://media/materials/scripts/gazebo.material</uri>
              <name>Gazebo/Wood</name>
            </script>
          </material>
        </visual>
        <collision name='right_handle_bo'>
          <pose frame=''>0.02475 -0.2555 -0.06542 0 -0 0</pose>
          <geometry>
            <box>
              <size>0.04 0.005 0.005</size>
            </box>
          </geometry>
          <max_contacts>10</max_contacts>
          <surface>
            <contact/>
            <friction>
              <ode/>
            </friction>
          </surface>
        </collision>
        <visual name='right_handle_bo_vis'>
          <pose frame=''>0.02475 -0.2555 -0.06542 0 -0 0</pose>
          <geometry>
            <box>
              <size>0.04 0.005 0.005</size>
            </box>
          </geometry>
          <material>
            <script>
              <uri>file://media/materials/scripts/gazebo.material</uri>
              <name>Gazebo/Wood</name>
            </script>
          </material>
        </visual>
        <visual name='visual_marker_0'>
          <pose frame=''>0.007 -0.07 0 1.57075 0 1.57075</pose>
          <geometry>
            <mesh>
              <uri>model://marker_0/meshes/marker_0.dae</uri>
            </mesh>
          </geometry>
        </visual>
        <self_collide>0</self_collide>
        <enable_wind>0</enable_wind>
        <gravity>1</gravity>
      </link>
      <joint name='right_handle_joint' type='revolute'>
        <parent>right_door</parent>
        <child>right_handle_dummy</child>
        <axis>
          <xyz>0 1 0</xyz>
          <limit>
            <lower>-3.1</lower>
            <upper>3.1</upper>
          </limit>
          <dynamics>
            <damping>0.01</damping>
            <friction>1</friction>
            <spring_reference>0</spring_reference>
            <spring_stiffness>0</spring_stiffness>
          </dynamics>
          <use_parent_model_frame>1</use_parent_model_frame>
        </axis>
        <pose frame=''>0 0 0 0 -0 0</pose>
      </joint>
      <link name='right_handle_dummy'>
        <pose frame=''>0.17804 0.028 0.3195 0 -0 0</pose>
        <inertial>
          <mass>0.1</mass>
          <pose frame=''>0 0 0.068 0 -0 0</pose>
          <inertia>
            <ixx>0.000154133</ixx>
            <ixy>0</ixy>
            <ixz>0</ixz>
            <iyy>0.000154133</iyy>
            <iyz>0</iyz>
            <izz>0.000154133</izz>
          </inertia>
        </inertial>
        <self_collide>0</self_collide>
        <enable_wind>0</enable_wind>
        <gravity>1</gravity>
      </link>
      <joint name='right_handle_joint2' type='revolute'>
        <parent>right_handle_dummy</parent>
        <child>right_handle</child>
        <axis>
          <xyz>1 0 0</xyz>
          <limit>
            <lower>-3.1</lower>
            <upper>3.1</upper>
          </limit>
          <dynamics>
            <damping>0.01</damping>
            <friction>1</friction>
            <spring_reference>0</spring_reference>
            <spring_stiffness>0</spring_stiffness>
          </dynamics>
          <use_parent_model_frame>1</use_parent_model_frame>
        </axis>
        <pose frame=''>0 0 0 0 -0 0</pose>
      </joint>
      <link name='right_handle'>
        <pose frame=''>0.17804 0.028 0.3195 0 -0 0</pose>
        <inertial>
          <mass>0.1</mass>
          <pose frame=''>0 0 0.068 0 -0 0</pose>
          <inertia>
            <ixx>0.000154133</ixx>
            <ixy>0</ixy>
            <ixz>0</ixz>
            <iyy>0.000154133</iyy>
            <iyz>0</iyz>
            <izz>0.000154133</izz>
          </inertia>
        </inertial>
        <collision name='right_handle'>
          <pose frame=''>0 0 0.068 0 -0 0</pose>
          <geometry>
            <box>
              <size>0.005 0.005 0.136</size>
            </box>
          </geometry>
          <max_contacts>10</max_contacts>
          <surface>
            <contact/>
            <friction>
              <ode/>
            </friction>
          </surface>
        </collision>
        <visual name='right_handle_vis'>
          <pose frame=''>0 0 0.068 0 -0 0</pose>
          <geometry>
            <box>
              <size>0.005 0.005 0.136</size>
            </box>
          </geometry>
          <material>
            <script>
              <uri>file://media/materials/scripts/gazebo.material</uri>
              <name>Gazebo/Wood</name>
            </script>
          </material>
        </visual>
        <self_collide>0</self_collide>
        <enable_wind>0</enable_wind>
        <gravity>1</gravity>
      </link>
      <joint name='right_joint' type='revolute'>
        <parent>cabinet</parent>
        <child>right_door</child>
        <axis>
          <xyz>0 0 1</xyz>
          <limit>
            <lower>-0.001</lower>
            <upper>2.36</upper>
          </limit>
          <dynamics>
            <damping>0.5</damping>
            <friction>0.1</friction>
            <spring_reference>0</spring_reference>
            <spring_stiffness>0</spring_stiffness>
          </dynamics>
          <use_parent_model_frame>1</use_parent_model_frame>
        </axis>
        <pose frame=''>0 0 0 0 -0 0</pose>
      </joint>
      <link name='left_door'>
        <pose frame=''>0.135 -0.2835 0.3875 0 -0 0</pose>
        <inertial>
          <mass>1</mass>
          <pose frame=''>0 0.141 0 0 -0 0</pose>
          <inertia>
            <ixx>0.06</ixx>
            <ixy>0</ixy>
            <ixz>0</ixz>
            <iyy>0.49</iyy>
            <iyz>0</iyz>
            <izz>0.111</izz>
          </inertia>
        </inertial>
        <collision name='left_face'>
          <pose frame=''>0 0.141 0 0 -0 0</pose>
          <geometry>
            <box>
              <size>0.015 0.282 0.595</size>
            </box>
          </geometry>
          <max_contacts>10</max_contacts>
          <surface>
            <contact/>
            <friction>
              <ode/>
            </friction>
          </surface>
        </collision>
        <visual name='left_face_vis'>
          <pose frame=''>0 0.141 0 0 -0 0</pose>
          <geometry>
            <box>
              <size>0.015 0.282 0.595</size>
            </box>
          </geometry>
          <material>
            <script>
              <uri>file://media/materials/scripts/gazebo.material</uri>
              <name>Gazebo/Wood</name>
            </script>
          </material>
        </visual>
        <collision name='left_handle_up'>
          <pose frame=''>0.02475 0.2555 0.0656 0 -0 0</pose>
          <geometry>
            <box>
              <size>0.04 0.005 0.005</size>
            </box>
          </geometry>
          <max_contacts>10</max_contacts>
          <surface>
            <contact/>
            <friction>
              <ode/>
            </friction>
          </surface>
        </collision>
        <visual name='left_handle_up_vis'>
          <pose frame=''>0.02475 0.2555 0.0656 0 -0 0</pose>
          <geometry>
            <box>
              <size>0.04 0.005 0.005</size>
            </box>
          </geometry>
          <material>
            <script>
              <uri>file://media/materials/scripts/gazebo.material</uri>
              <name>Gazebo/Wood</name>
            </script>
          </material>
        </visual>
        <collision name='left_handle_bo'>
          <pose frame=''>0.02475 0.2555 -0.06542 0 -0 0</pose>
          <geometry>
            <box>
              <size>0.04 0.005 0.005</size>
            </box>
          </geometry>
          <max_contacts>10</max_contacts>
          <surface>
            <contact/>
            <friction>
              <ode/>
            </friction>
          </surface>
        </collision>
        <visual name='left_handle_bo_vis'>
          <pose frame=''>0.02475 0.2555 -0.06542 0 -0 0</pose>
          <geometry>
            <box>
              <size>0.04 0.005 0.005</size>
            </box>
          </geometry>
          <material>
            <script>
              <uri>file://media/materials/scripts/gazebo.material</uri>
              <name>Gazebo/Wood</name>
            </script>
          </material>
        </visual>
        <self_collide>0</self_collide>
        <enable_wind>0</enable_wind>
        <gravity>1</gravity>
      </link>
      <joint name='left_joint' type='revolute'>
        <parent>cabinet</parent>
        <child>left_door</child>
        <axis>
          <xyz>0 0 1</xyz>
          <limit>
            <lower>-2.36</lower>
            <upper>0.001</upper>
          </limit>
          <dynamics>
            <damping>0.5</damping>
            <friction>0.1</friction>
            <spring_reference>0</spring_reference>
            <spring_stiffness>0</spring_stiffness>
          </dynamics>
          <use_parent_model_frame>1</use_parent_model_frame>
        </axis>
        <pose frame=''>0 0 0 0 -0 0</pose>
      </joint>
      <joint name='left_handle_joint' type='revolute'>
        <parent>left_door</parent>
        <child>left_handle_dummy</child>
        <axis>
          <xyz>0 1 0</xyz>
          <limit>
            <lower>-3.1</lower>
            <upper>3.1</upper>
          </limit>
          <dynamics>
            <damping>0.01</damping>
            <friction>1</friction>
            <spring_reference>0</spring_reference>
            <spring_stiffness>0</spring_stiffness>
          </dynamics>
          <use_parent_model_frame>1</use_parent_model_frame>
        </axis>
        <pose frame=''>0 0 0 0 -0 0</pose>
      </joint>
      <link name='left_handle_dummy'>
        <pose frame=''>0.17804 -0.028 0.3195 0 -0 0</pose>
        <inertial>
          <mass>0.1</mass>
          <pose frame=''>0 0 0.068 0 -0 0</pose>
          <inertia>
            <ixx>0.000154133</ixx>
            <ixy>0</ixy>
            <ixz>0</ixz>
            <iyy>0.000154133</iyy>
            <iyz>0</iyz>
            <izz>0.000154133</izz>
          </inertia>
        </inertial>
        <self_collide>0</self_collide>
        <enable_wind>0</enable_wind>
        <gravity>1</gravity>
      </link>
      <joint name='left_handle_joint2' type='revolute'>
        <parent>left_handle_dummy</parent>
        <child>left_handle</child>
        <axis>
          <xyz>1 0 0</xyz>
          <limit>
            <lower>-3.1</lower>
            <upper>3.1</upper>
          </limit>
          <dynamics>
            <damping>0.01</damping>
            <friction>1</friction>
            <spring_reference>0</spring_reference>
            <spring_stiffness>0</spring_stiffness>
          </dynamics>
          <use_parent_model_frame>1</use_parent_model_frame>
        </axis>
        <pose frame=''>0 0 0 0 -0 0</pose>
      </joint>
      <link name='left_handle'>
        <pose frame=''>0.17804 -0.028 0.3195 0 -0 0</pose>
        <inertial>
          <mass>0.1</mass>
          <pose frame=''>0 0 0.068 0 -0 0</pose>
          <inertia>
            <ixx>0.000154133</ixx>
            <ixy>0</ixy>
            <ixz>0</ixz>
            <iyy>0.000154133</iyy>
            <iyz>0</iyz>
            <izz>0.000154133</izz>
          </inertia>
        </inertial>
        <collision name='left_handle'>
          <pose frame=''>0 0 0.068 0 -0 0</pose>
          <geometry>
            <box>
              <size>0.005 0.005 0.136</size>
            </box>
          </geometry>
          <max_contacts>10</max_contacts>
          <surface>
            <contact/>
            <friction>
              <ode/>
            </friction>
          </surface>
        </collision>
        <visual name='left_handle_vis'>
          <pose frame=''>0 0 0.068 0 -0 0</pose>
          <geometry>
            <box>
              <size>0.005 0.005 0.136</size>
            </box>
          </geometry>
          <material>
            <script>
              <uri>file://media/materials/scripts/gazebo.material</uri>
              <name>Gazebo/Wood</name>
            </script>
          </material>
        </visual>
        <self_collide>0</self_collide>
        <enable_wind>0</enable_wind>
        <gravity>1</gravity>
      </link>
      <pose frame=''>0.750235 3.09394 0 0 -0 0</pose>
    </model>
    <model name='cafe_table_clone'>
      <static>1</static>
      <link name='link'>
        <collision name='surface'>
          <pose frame=''>0 0 0.755 0 -0 0</pose>
          <geometry>
            <box>
              <size>0.913 0.913 0.04</size>
            </box>
          </geometry>
          <max_contacts>10</max_contacts>
          <surface>
            <contact/>
            <friction>
              <ode/>
            </friction>
          </surface>
        </collision>
        <collision name='column'>
          <pose frame=''>0 0 0.37 0 -0 0</pose>
          <geometry>
            <box>
              <size>0.042 0.042 0.74</size>
            </box>
          </geometry>
          <max_contacts>10</max_contacts>
          <surface>
            <contact/>
            <friction>
              <ode/>
            </friction>
          </surface>
        </collision>
        <collision name='base'>
          <pose frame=''>0 0 0.02 0 -0 0</pose>
          <geometry>
            <box>
              <size>0.56 0.56 0.04</size>
            </box>
          </geometry>
          <max_contacts>10</max_contacts>
          <surface>
            <contact/>
            <friction>
              <ode/>
            </friction>
          </surface>
        </collision>
        <visual name='visual'>
          <geometry>
            <mesh>
              <uri>model://cafe_table/meshes/cafe_table.dae</uri>
            </mesh>
          </geometry>
        </visual>
        <self_collide>0</self_collide>
        <enable_wind>0</enable_wind>
        <gravity>1</gravity>
      </link>
      <pose frame=''>1.06553 -0.004123 0 0 -0 0</pose>
    </model>
    <model name='cafe_table_clone_clone'>
      <static>1</static>
      <link name='link'>
        <collision name='surface'>
          <pose frame=''>0 0 0.755 0 -0 0</pose>
          <geometry>
            <box>
              <size>0.913 0.913 0.04</size>
            </box>
          </geometry>
          <max_contacts>10</max_contacts>
          <surface>
            <contact/>
            <friction>
              <ode/>
            </friction>
          </surface>
        </collision>
        <collision name='column'>
          <pose frame=''>0 0 0.37 0 -0 0</pose>
          <geometry>
            <box>
              <size>0.042 0.042 0.74</size>
            </box>
          </geometry>
          <max_contacts>10</max_contacts>
          <surface>
            <contact/>
            <friction>
              <ode/>
            </friction>
          </surface>
        </collision>
        <collision name='base'>
          <pose frame=''>0 0 0.02 0 -0 0</pose>
          <geometry>
            <box>
              <size>0.56 0.56 0.04</size>
            </box>
          </geometry>
          <max_contacts>10</max_contacts>
          <surface>
            <contact/>
            <friction>
              <ode/>
            </friction>
          </surface>
        </collision>
        <visual name='visual'>
          <geometry>
            <mesh>
              <uri>model://cafe_table/meshes/cafe_table.dae</uri>
            </mesh>
          </geometry>
        </visual>
        <self_collide>0</self_collide>
        <enable_wind>0</enable_wind>
        <gravity>1</gravity>
      </link>
      <pose frame=''>-1.25276 -1.22091 0 0 -0 0</pose>
    </model>
    <model name='demo_spam'>
      <static>0</static>
      <link name='link'>
        <inertial>
          <mass>0.25</mass>
          <inertia>
            <ixx>0.00015</ixx>
            <ixy>0</ixy>
            <ixz>0</ixz>
            <iyy>0.00015</iyy>
            <iyz>0</iyz>
            <izz>0.00015</izz>
          </inertia>
          <pose frame=''>0 0 0 0 -0 0</pose>
        </inertial>
        <collision name='collision'>
          <geometry>
            <box>
              <size>0.102 0.0601 0.0835</size>
            </box>
          </geometry>
          <surface>
            <friction>
              <ode>
                <mu>30</mu>
                <mu2>30</mu2>
              </ode>
            </friction>
            <contact>
              <ode>
                <kp>1e+06</kp>
                <kd>100</kd>
                <max_vel>1</max_vel>
                <min_depth>0.002</min_depth>
              </ode>
            </contact>
          </surface>
          <max_contacts>10</max_contacts>
        </collision>
        <visual name='visual'>
          <geometry>
            <mesh>
              <uri>model://demo_spam/meshes/nontextured_fixed.stl</uri>
              <scale>1 1 1</scale>
            </mesh>
          </geometry>
          <material>
            <script>
              <uri>file://media/materials/scripts/gazebo.material</uri>
              <name>Gazebo/Green</name>
            </script>
          </material>
        </visual>
        <velocity_decay>
          <linear>0</linear>
          <angular>0</angular>
        </velocity_decay>
        <self_collide>0</self_collide>
        <kinematic>0</kinematic>
        <gravity>1</gravity>
        <enable_wind>0</enable_wind>
      </link>
      <pose frame=''>-1.17118 -1.60198 0 0 -0 0</pose>
    </model>
    <model name='teapot'>
      <static>0</static>
      <link name='link'>
        <inertial>
          <mass>0.25</mass>
          <inertia>
            <ixx>0.00015</ixx>
            <ixy>0</ixy>
            <ixz>0</ixz>
            <iyy>0.00015</iyy>
            <iyz>0</iyz>
            <izz>0.00015</izz>
          </inertia>
          <pose frame=''>0 0 0 0 -0 0</pose>
        </inertial>
        <collision name='collision'>
          <geometry>
            <mesh>
              <uri>model://teapot/meshes/teapot.stl</uri>
              <scale>2 2 2</scale>
            </mesh>
          </geometry>
          <surface>
            <friction>
              <ode>
                <mu>30</mu>
                <mu2>30</mu2>
              </ode>
            </friction>
            <contact>
              <ode>
                <kp>1e+06</kp>
                <kd>100</kd>
                <max_vel>1</max_vel>
                <min_depth>0.002</min_depth>
              </ode>
            </contact>
          </surface>
          <max_contacts>10</max_contacts>
        </collision>
        <visual name='visual'>
          <geometry>
            <mesh>
              <uri>model://teapot/meshes/teapot.stl</uri>
              <scale>2 2 2</scale>
            </mesh>
          </geometry>
          <material>
            <script>
              <uri>file://media/materials/scripts/gazebo.material</uri>
              <name>Gazebo/Blue</name>
            </script>
          </material>
        </visual>
        <velocity_decay>
          <linear>0</linear>
          <angular>0</angular>
        </velocity_decay>
        <self_collide>0</self_collide>
        <kinematic>0</kinematic>
        <gravity>1</gravity>
        <enable_wind>0</enable_wind>
      </link>
      <pose frame=''>1.17208 -0.010298 0 0 -0 0</pose>
    </model>
  </world>
</sdf>
